[2023-01-30T15:49:39.707+0000] {taskinstance.py:1165} INFO - Dependencies all met for <TaskInstance: user_processing.process_user manual__2023-01-30T15:49:38.448413+00:00 [queued]>
[2023-01-30T15:49:39.718+0000] {taskinstance.py:1165} INFO - Dependencies all met for <TaskInstance: user_processing.process_user manual__2023-01-30T15:49:38.448413+00:00 [queued]>
[2023-01-30T15:49:39.720+0000] {taskinstance.py:1362} INFO - 
--------------------------------------------------------------------------------
[2023-01-30T15:49:39.722+0000] {taskinstance.py:1363} INFO - Starting attempt 1 of 1
[2023-01-30T15:49:39.723+0000] {taskinstance.py:1364} INFO - 
--------------------------------------------------------------------------------
[2023-01-30T15:49:39.740+0000] {taskinstance.py:1383} INFO - Executing <Task(PythonOperator): process_user> on 2023-01-30 15:49:38.448413+00:00
[2023-01-30T15:49:39.759+0000] {standard_task_runner.py:55} INFO - Started process 2764 to run task
[2023-01-30T15:49:39.783+0000] {standard_task_runner.py:82} INFO - Running: ['***', 'tasks', 'run', 'user_processing', 'process_user', 'manual__2023-01-30T15:49:38.448413+00:00', '--job-id', '17', '--raw', '--subdir', 'DAGS_FOLDER/user_processing.py', '--cfg-path', '/tmp/tmpctvkjih8']
[2023-01-30T15:49:39.791+0000] {standard_task_runner.py:83} INFO - Job 17: Subtask process_user
[2023-01-30T15:49:40.036+0000] {task_command.py:376} INFO - Running <TaskInstance: user_processing.process_user manual__2023-01-30T15:49:38.448413+00:00 [running]> on host 3c28126f9714
[2023-01-30T15:49:40.298+0000] {taskinstance.py:1592} INFO - Exporting the following env vars:
AIRFLOW_CTX_DAG_OWNER=***
AIRFLOW_CTX_DAG_ID=user_processing
AIRFLOW_CTX_TASK_ID=process_user
AIRFLOW_CTX_EXECUTION_DATE=2023-01-30T15:49:38.448413+00:00
AIRFLOW_CTX_TRY_NUMBER=1
AIRFLOW_CTX_DAG_RUN_ID=manual__2023-01-30T15:49:38.448413+00:00
[2023-01-30T15:49:40.347+0000] {taskinstance.py:1851} ERROR - Task failed with exception
Traceback (most recent call last):
  File "/home/airflow/.local/lib/python3.7/site-packages/airflow/operators/python.py", line 175, in execute
    return_value = self.execute_callable()
  File "/home/airflow/.local/lib/python3.7/site-packages/airflow/operators/python.py", line 193, in execute_callable
    return self.python_callable(*self.op_args, **self.op_kwargs)
  File "/opt/airflow/dags/user_processing.py", line 14, in _process_user
    user = user_raw['results'][0]
TypeError: 'NoneType' object is not subscriptable
[2023-01-30T15:49:40.376+0000] {taskinstance.py:1406} INFO - Marking task as FAILED. dag_id=user_processing, task_id=process_user, execution_date=20230130T154938, start_date=20230130T154939, end_date=20230130T154940
[2023-01-30T15:49:40.397+0000] {standard_task_runner.py:105} ERROR - Failed to execute job 17 for task process_user ('NoneType' object is not subscriptable; 2764)
[2023-01-30T15:49:40.425+0000] {local_task_job.py:164} INFO - Task exited with return code 1
[2023-01-30T15:49:40.466+0000] {local_task_job.py:273} INFO - 0 downstream tasks scheduled from follow-on schedule check
